Workbook
Name Slicer_Stage_Name_: #N/A

Sheet Instructions
C2: Case Study
C3: Instructions
C16: Given:
C22: Prompts:

Sheet Pipeline Data
A1: Talent ID | B1: Talent ID_ | C1: Recruiter | D1: Region | E1: Stage Name | F1: Stage Name_ | G1: Entered Date | H1: Month
A2: 165728887129 | B2: =TEXT(A2,"0") -> 165728887129 | C2: =_xlfn.XLOOKUP( B2, 'Candidate Data'!A:A, 'Candidate Data'!B:B, "Not Found" ) -> Recruiter1 | D2: =_xlfn.XLOOKUP( C2, 'Recruiter Data'!A:A, 'Recruiter Data'!B:B, "Unknown" ) -> N America | E2: Application Review | F2: =IF(ISNUMBER(SEARCH("Phone Screen",E2)),"Phone Screen", IF(ISNUMBER(SEARCH("Interview #1",E2)),"Interview #1", IF(ISNUMBER(SEARCH("Final Interview",E2)),"Final Interview", IF(ISNUMBER(SEARCH("Next Steps",E2)),"Next Steps", IF(ISNUMBER(SEARCH("Diligence",E2)),"Diligence", IF(ISNUMBER(SEARCH("Waitlist",E2)),"Waitlist", "Application Review")))))) -> Application Review | G2: 44665.586 | H2: =TEXT(G2,"yyyy-mm") -> 2022-04
A3: 165728887129 | B3: =TEXT(A3,"0") -> 165728887129 | C3: =_xlfn.XLOOKUP( B3, 'Candidate Data'!A:A, 'Candidate Data'!B:B, "Not Found" ) -> Recruiter1 | D3: =_xlfn.XLOOKUP( C3, 'Recruiter Data'!A:A, 'Recruiter Data'!B:B, "Unknown" ) -> N America | E3: LT | Phone Screen | F3: =IF(ISNUMBER(SEARCH("Phone Screen",E3)),"Phone Screen", IF(ISNUMBER(SEARCH("Interview #1",E3)),"Interview #1", IF(ISNUMBER(SEARCH("Final Interview",E3)),"Final Interview", IF(ISNUMBER(SEARCH("Next Steps",E3)),"Next Steps", IF(ISNUMBER(SEARCH("Diligence",E3)),"Diligence", IF(ISNUMBER(SEARCH("Waitlist",E3)),"Waitlist", "Application Review")))))) -> Phone Screen | G3: 44665.586 | H3: =TEXT(G3,"yyyy-mm") -> 2022-04
A4: 165939190717 | B4: =TEXT(A4,"0") -> 165939190717 | C4: =_xlfn.XLOOKUP( B4, 'Candidate Data'!A:A, 'Candidate Data'!B:B, "Not Found" ) -> Recruiter2 | D4: =_xlfn.XLOOKUP( C4, 'Recruiter Data'!A:A, 'Recruiter Data'!B:B, "Unknown" ) -> N America | E4: Application Review | F4: =IF(ISNUMBER(SEARCH("Phone Screen",E4)),"Phone Screen", IF(ISNUMBER(SEARCH("Interview #1",E4)),"Interview #1", IF(ISNUMBER(SEARCH("Final Interview",E4)),"Final Interview", IF(ISNUMBER(SEARCH("Next Steps",E4)),"Next Steps", IF(ISNUMBER(SEARCH("Diligence",E4)),"Diligence", IF(ISNUMBER(SEARCH("Waitlist",E4)),"Waitlist", "Application Review")))))) -> Application Review | G4: 44669.758 | H4: =TEXT(G4,"yyyy-mm") -> 2022-04
A5: 165939190717 | B5: =TEXT(A5,"0") -> 165939190717 | C5: =_xlfn.XLOOKUP( B5, 'Candidate Data'!A:A, 'Candidate Data'!B:B, "Not Found" ) -> Recruiter2 | D5: =_xlfn.XLOOKUP( C5, 'Recruiter Data'!A:A, 'Recruiter Data'!B:B, "Unknown" ) -> N America | E5: LT | Interview #1 | F5: =IF(ISNUMBER(SEARCH("Phone Screen",E5)),"Phone Screen", IF(ISNUMBER(SEARCH("Interview #1",E5)),"Interview #1", IF(ISNUMBER(SEARCH("Final Interview",E5)),"Final Interview", IF(ISNUMBER(SEARCH("Next Steps",E5)),"Next Steps", IF(ISNUMBER(SEARCH("Diligence",E5)),"Diligence", IF(ISNUMBER(SEARCH("Waitlist",E5)),"Waitlist", "Application Review")))))) -> Interview #1 | G5: 44669.772 | H5: =TEXT(G5,"yyyy-mm") -> 2022-04
A6: 165939190717 | B6: =TEXT(A6,"0") -> 165939190717 | C6: =_xlfn.XLOOKUP( B6, 'Candidate Data'!A:A, 'Candidate Data'!B:B, "Not Found" ) -> Recruiter2 | D6: =_xlfn.XLOOKUP( C6, 'Recruiter Data'!A:A, 'Recruiter Data'!B:B, "Unknown" ) -> N America | E6: LT | Phone Screen | F6: =IF(ISNUMBER(SEARCH("Phone Screen",E6)),"Phone Screen", IF(ISNUMBER(SEARCH("Interview #1",E6)),"Interview #1", IF(ISNUMBER(SEARCH("Final Interview",E6)),"Final Interview", IF(ISNUMBER(SEARCH("Next Steps",E6)),"Next Steps", IF(ISNUMBER(SEARCH("Diligence",E6)),"Diligence", IF(ISNUMBER(SEARCH("Waitlist",E6)),"Waitlist", "Application Review")))))) -> Phone Screen | G6: 44669.758 | H6: =TEXT(G6,"yyyy-mm") -> 2022-04
A7: 128587529341 | B7: =TEXT(A7,"0") -> 128587529341 | C7: =_xlfn.XLOOKUP( B7, 'Candidate Data'!A:A, 'Candidate Data'!B:B, "Not Found" ) -> Recruiter21 | D7: =_xlfn.XLOOKUP( C7, 'Recruiter Data'!A:A, 'Recruiter Data'!B:B, "Unknown" ) -> Europe | E7: LT | Phone Screen | F7: =IF(ISNUMBER(SEARCH("Phone Screen",E7)),"Phone Screen", IF(ISNUMBER(SEARCH("Interview #1",E7)),"Interview #1", IF(ISNUMBER(SEARCH("Final Interview",E7)),"Final Interview", IF(ISNUMBER(SEARCH("Next Steps",E7)),"Next Steps", IF(ISNUMBER(SEARCH("Diligence",E7)),"Diligence", IF(ISNUMBER(SEARCH("Waitlist",E7)),"Waitlist", "Application Review")))))) -> Phone Screen | G7: 44666.766 | H7: =TEXT(G7,"yyyy-mm") -> 2022-04
A8: 128601241951 | B8: =TEXT(A8,"0") -> 128601241951 | C8: =_xlfn.XLOOKUP( B8, 'Candidate Data'!A:A, 'Candidate Data'!B:B, "Not Found" ) -> Recruiter3 | D8: =_xlfn.XLOOKUP( C8, 'Recruiter Data'!A:A, 'Recruiter Data'!B:B, "Unknown" ) -> N America | E8: Application Review | F8: =IF(ISNUMBER(SEARCH("Phone Screen",E8)),"Phone Screen", IF(ISNUMBER(SEARCH("Interview #1",E8)),"Interview #1", IF(ISNUMBER(SEARCH("Final Interview",E8)),"Final Interview", IF(ISNUMBER(SEARCH("Next Steps",E8)),"Next Steps", IF(ISNUMBER(SEARCH("Diligence",E8)),"Diligence", IF(ISNUMBER(SEARCH("Waitlist",E8)),"Waitlist", "Application Review")))))) -> Application Review | G8: 44661.617 | H8: =TEXT(G8,"yyyy-mm") -> 2022-04
A9: 128601241951 | B9: =TEXT(A9,"0") -> 128601241951 | C9: =_xlfn.XLOOKUP( B9, 'Candidate Data'!A:A, 'Candidate Data'!B:B, "Not Found" ) -> Recruiter3 | D9: =_xlfn.XLOOKUP( C9, 'Recruiter Data'!A:A, 'Recruiter Data'!B:B, "Unknown" ) -> N America | E9: LT | Interview #1 | F9: =IF(ISNUMBER(SEARCH("Phone Screen",E9)),"Phone Screen", IF(ISNUMBER(SEARCH("Interview #1",E9)),"Interview #1", IF(ISNUMBER(SEARCH("Final Interview",E9)),"Final Interview", IF(ISNUMBER(SEARCH("Next Steps",E9)),"Next Steps", IF(ISNUMBER(SEARCH("Diligence",E9)),"Diligence", IF(ISNUMBER(SEARCH("Waitlist",E9)),"Waitlist", "Application Review")))))) -> Interview #1 | G9: 44661.617 | H9: =TEXT(G9,"yyyy-mm") -> 2022-04
A10: 128601241951 | B10: =TEXT(A10,"0") -> 128601241951 | C10: =_xlfn.XLOOKUP( B10, 'Candidate Data'!A:A, 'Candidate Data'!B:B, "Not Found" ) -> Recruiter3 | D10: =_xlfn.XLOOKUP( C10, 'Recruiter Data'!A:A, 'Recruiter Data'!B:B, "Unknown" ) -> N America | E10: LT | Phone Screen | F10: =IF(ISNUMBER(SEARCH("Phone Screen",E10)),"Phone Screen", IF(ISNUMBER(SEARCH("Interview #1",E10)),"Interview #1", IF(ISNUMBER(SEARCH("Final Interview",E10)),"Final Interview", IF(ISNUMBER(SEARCH("Next Steps",E10)),"Next Steps", IF(ISNUMBER(SEARCH("Diligence",E10)),"Diligence", IF(ISNUMBER(SEARCH("Waitlist",E10)),"Waitlist", "Application Review")))))) -> Phone Screen | G10: 44661.617 | H10: =TEXT(G10,"yyyy-mm") -> 2022-04
A11: 128574298299 | B11: =TEXT(A11,"0") -> 128574298299 | C11: =_xlfn.XLOOKUP( B11, 'Candidate Data'!A:A, 'Candidate Data'!B:B, "Not Found" ) -> Recruiter4 | D11: =_xlfn.XLOOKUP( C11, 'Recruiter Data'!A:A, 'Recruiter Data'!B:B, "Unknown" ) -> Asia | E11: Application Review | F11: =IF(ISNUMBER(SEARCH("Phone Screen",E11)),"Phone Screen", IF(ISNUMBER(SEARCH("Interview #1",E11)),"Interview #1", IF(ISNUMBER(SEARCH("Final Interview",E11)),"Final Interview", IF(ISNUMBER(SEARCH("Next Steps",E11)),"Next Steps", IF(ISNUMBER(SEARCH("Diligence",E11)),"Diligence", IF(ISNUMBER(SEARCH("Waitlist",E11)),"Waitlist", "Application Review")))))) -> Application Review | G11: 44637.392 | H11: =TEXT(G11,"yyyy-mm") -> 2022-03
A12: 128574298299 | B12: =TEXT(A12,"0") -> 128574298299 | C12: =_xlfn.XLOOKUP( B12, 'Candidate Data'!A:A, 'Candidate Data'!B:B, "Not Found" ) -> Recruiter4 | D12: =_xlfn.XLOOKUP( C12, 'Recruiter Data'!A:A, 'Recruiter Data'!B:B, "Unknown" ) -> Asia | E12: LT | Diligence | F12: =IF(ISNUMBER(SEARCH("Phone Screen",E12)),"Phone Screen", IF(ISNUMBER(SEARCH("Interview #1",E12)),"Interview #1", IF(ISNUMBER(SEARCH("Final Interview",E12)),"Final Interview", IF(ISNUMBER(SEARCH("Next Steps",E12)),"Next Steps", IF(ISNUMBER(SEARCH("Diligence",E12)),"Diligence", IF(ISNUMBER(SEARCH("Waitlist",E12)),"Waitlist", "Application Review")))))) -> Diligence | G12: 44637.393 | H12: =TEXT(G12,"yyyy-mm") -> 2022-03
A13: 128574298299 | B13: =TEXT(A13,"0") -> 128574298299 | C13: =_xlfn.XLOOKUP( B13, 'Candidate Data'!A:A, 'Candidate Data'!B:B, "Not Found" ) -> Recruiter4 | D13: =_xlfn.XLOOKUP( C13, 'Recruiter Data'!A:A, 'Recruiter Data'!B:B, "Unknown" ) -> Asia | E13: LT | Final Interview | F13: =IF(ISNUMBER(SEARCH("Phone Screen",E13)),"Phone Screen", IF(ISNUMBER(SEARCH("Interview #1",E13)),"Interview #1", IF(ISNUMBER(SEARCH("Final Interview",E13)),"Final Interview", IF(ISNUMBER(SEARCH("Next Steps",E13)),"Next Steps", IF(ISNUMBER(SEARCH("Diligence",E13)),"Diligence", IF(ISNUMBER(SEARCH("Waitlist",E13)),"Waitlist", "Application Review")))))) -> Final Interview | G13: 44637.393 | H13: =TEXT(G13,"yyyy-mm") -> 2022-03
... A7132: 110113897902 | B7132: =TEXT(A7132,"0") -> 110113897902 | C7132: =_xlfn.XLOOKUP( B7132, 'Candidate Data'!A:A, 'Candidate Data'!B:B, "Not Found" ) -> Recruiter11 | D7132: =_xlfn.XLOOKUP( C7132, 'Recruiter Data'!A:A, 'Recruiter Data'!B:B, "Unknown" ) -> N America | E7132: LT | Phone Screen | F7132: =IF(ISNUMBER(SEARCH("Phone Screen",E7132)),"Phone Screen", IF(ISNUMBER(SEARCH("Interview #1",E7132)),"Interview #1", IF(ISNUMBER(SEARCH("Final Interview",E7132)),"Final Interview", IF(ISNUMBER(SEARCH("Next Steps",E7132)),"Next Steps", IF(ISNUMBER(SEARCH("Diligence",E7132)),"Diligence", IF(ISNUMBER(SEARCH("Waitlist",E7132)),"Waitlist", "Application Review")))))) -> Phone Screen | G7132: 44681.925 | H7132: =TEXT(G7132,"yyyy-mm") -> 2022-04

Sheet Candidate Data
A2: Talent ID | B2: Recruiter | C2: PQE | D2: LT - Practice Area
A3: 165728887129 | B3: Recruiter1 | C3: 35 | D3: Litigation, Investigations & Dispute Resolution
A4: 165939190717 | B4: Recruiter2 | C4: 18 | D4: Intellectual Property
A5: 128587529341 | B5: Recruiter21 | C5: 4 | D5: Commercial & Contract Law
A6: 128601241951 | B6: Recruiter3 | C6: 1 | D6: Regulatory & Compliance
A7: 128574298299 | B7: Recruiter4 | C7: 6 | D7: Finance
A8: 138168610686 | B8: Recruiter5 | C8: 50 | D8: Commercial & Contract Law
A9: 186131415350 | B9: Recruiter4 | C9: 32 | D9: Commercial & Contract Law
A10: 165686165802 | B10: Recruiter5 | C10: 7 | D10: Commercial & Contract Law
A11: 128659213037 | B11: Recruiter6 | C11: 8 | D11: Bankruptcy & Reorganization
A12: 103651899363 | B12: Recruiter7 | C12: 47 | D12: Commercial & Contract Law
A13: 128782123931 | B13: Recruiter3 | C13: 27 | D13: Commercial & Contract Law
A14: 173124722408 | B14: Recruiter20 | C14: 40 | D14: Bankruptcy & Reorganization
... A3498: 110113897902 | B3498: Recruiter11 | C3498: 7 | D3498: Commercial & Contract Law

Sheet Recruiter Data
A1: Recruiter | B1: Region
A2: Recruiter1 | B2: N America
A3: Recruiter2 | B3: N America
A4: Recruiter3 | B4: N America
A5: Recruiter4 | B5: Asia
A6: Recruiter5 | B6: Europe
A7: Recruiter6 | B7: N America
A8: Recruiter7 | B8: N America
A9: Recruiter8 | B9: Asia
A10: Recruiter9 | B10: Europe
A11: Recruiter10 | B11: N America
A12: Recruiter11 | B12: N America
... A57: Recruiter56 | B57: N America

Sheet Pivot
B2: Stage Name_ | C2: Phone Screen | E2: Stage Name_ | F2: Phone Screen | H2: Stage Name_ | I2: Waitlist | K2: Stage Name_ | L2: Waitlist
B4: Row Labels | C4: Count of Talent ID_ | E4: Row Labels | F4: Count of Talent ID_ | H4: Row Labels | I4: Count of Talent ID_ | K4: Row Labels | L4: Count of Talent ID_
B5: 2022-03 | C5: 539 | E5: Asia | F5: 98 | H5: Asia | I5: 38 | K5: 2022-03 | L5: 244
B6: 2022-04 | C6: 646 | E6: 2022-03 | F6: 55 | H6: 2022-03 | I6: 21 | K6: 2022-04 | L6: 213
B7: Grand Total | C7: 1185 | E7: 2022-04 | F7: 43 | H7: 2022-04 | I7: 17 | K7: Grand Total | L7: 457
E8: Europe | F8: 203 | H8: Europe | I8: 127
E9: 2022-03 | F9: 82 | H9: 2022-03 | I9: 80
E10: 2022-04 | F10: 121 | H10: 2022-04 | I10: 47
E11: N America | F11: 884 | H11: N America | I11: 292
E12: 2022-03 | F12: 402 | H12: 2022-03 | I12: 143
E13: 2022-04 | F13: 482 | H13: 2022-04 | I13: 149
E14: Grand Total | F14: 1185 | H14: Grand Total | I14: 457
B20: Count of Talent ID_ | C20: Column Labels
B21: Row Labels | C21: Application Review | D21: Diligence | E21: Final Interview | F21: Interview #1 | G21: Next Steps | H21: Phone Screen | I21: Waitlist | J21: Grand Total
B22: 2022-03 | C22: 1985 | D22: 199 | E22: 221 | F22: 328 | G22: 221 | H22: 539 | I22: 244 | J22: 3737
B23: 2022-04 | C23: 1455 | D23: 238 | E23: 244 | F23: 361 | G23: 237 | H23: 646 | I23: 213 | J23: 3394
B24: Grand Total | C24: 3440 | D24: 437 | E24: 465 | F24: 689 | G24: 458 | H24: 1185 | I24: 457 | J24: 7131

Sheet Conversion Analysis
A3: Distinct Count of Talent ID
B4: Phone Screen | C4: Waitlist | D4: Conversion Rate | G4: Distinct Count of Talent ID_ | H4: Column Labels
A5: Recruiter1 | B5: 133 | C5: 44 | D5: =IFERROR(C5/B5,0) -> 0.33082707 | G5: Row Labels | H5: Phone Screen | I5: Waitlist | J5: Conversion Rate | L5: Recruiters | M5: Phone Screen | N5: Waitlist | O5: Conversion Rate | P5: PQE | Q5: Practice Areas
A6: Recruiter2 | B6: 132 | C6: 41 | D6: =IFERROR(C6/B6,0) -> 0.31060606 | G6: Recruiter1 | H6: 133 | I6: 44 | J6: =IFERROR(I6/H6,0) -> 0.33082707 | L6: Recruiter9 | M6: 33 | N6: 34 | O6: =IFERROR(N6/M6,0) -> 1.030303 | P6: =_xlfn.XLOOKUP( L6, 'Candidate Data'!B:B, 'Candidate Data'!C:C, "Not Found" ) -> 2 | Q6: =_xlfn.XLOOKUP( L6, 'Candidate Data'!B:B, 'Candidate Data'!D:D, "Not Found" ) -> Data Privacy & Cybersecurity
A7: Recruiter10 | B7: 111 | C7: 40 | D7: =IFERROR(C7/B7,0) -> 0.36036036 | G7: Recruiter10 | H7: 111 | I7: 40 | J7: =IFERROR(I7/H7,0) -> 0.36036036 | L7: Recruiter28 | M7: 26 | N7: 23 | O7: =IFERROR(N7/M7,0) -> 0.88461538 | P7: =_xlfn.XLOOKUP( L7, 'Candidate Data'!B:B, 'Candidate Data'!C:C, "Not Found" ) -> 34 | Q7: =_xlfn.XLOOKUP( L7, 'Candidate Data'!B:B, 'Candidate Data'!D:D, "Not Found" ) -> Commercial & Contract Law
A8: Recruiter21 | B8: 44 | C8: 38 | D8: =IFERROR(C8/B8,0) -> 0.86363636 | G8: Recruiter11 | H8: 121 | I8: 27 | J8: =IFERROR(I8/H8,0) -> 0.2231405 | L8: Recruiter21 | M8: 44 | N8: 38 | O8: =IFERROR(N8/M8,0) -> 0.86363636 | P8: =_xlfn.XLOOKUP( L8, 'Candidate Data'!B:B, 'Candidate Data'!C:C, "Not Found" ) -> 4 | Q8: =_xlfn.XLOOKUP( L8, 'Candidate Data'!B:B, 'Candidate Data'!D:D, "Not Found" ) -> Commercial & Contract Law
A9: Recruiter9 | B9: 33 | C9: 34 | D9: =IFERROR(C9/B9,0) -> 1.030303 | G9: Recruiter15 | H9: 57 | I9: 15 | J9: =IFERROR(I9/H9,0) -> 0.26315789 | L9: Recruiter3 | M9: 37 | N9: 26 | O9: =IFERROR(N9/M9,0) -> 0.7027027 | P9: =_xlfn.XLOOKUP( L9, 'Candidate Data'!B:B, 'Candidate Data'!C:C, "Not Found" ) -> 1 | Q9: =_xlfn.XLOOKUP( L9, 'Candidate Data'!B:B, 'Candidate Data'!D:D, "Not Found" ) -> Regulatory & Compliance
A10: Recruiter7 | B10: 48 | C10: 30 | D10: =IFERROR(C10/B10,0) -> 0.625 | G10: Recruiter2 | H10: 132 | I10: 41 | J10: =IFERROR(I10/H10,0) -> 0.31060606 | L10: Recruiter8 | M10: 20 | N10: 13 | O10: =IFERROR(N10/M10,0) -> 0.65 | P10: =_xlfn.XLOOKUP( L10, 'Candidate Data'!B:B, 'Candidate Data'!C:C, "Not Found" ) -> 47 | Q10: =_xlfn.XLOOKUP( L10, 'Candidate Data'!B:B, 'Candidate Data'!D:D, "Not Found" ) -> Finance
A11: Recruiter11 | B11: 121 | C11: 27 | D11: =IFERROR(C11/B11,0) -> 0.2231405 | G11: Recruiter21 | H11: 44 | I11: 38 | J11: =IFERROR(I11/H11,0) -> 0.86363636 | L11: Recruiter7 | M11: 48 | N11: 30 | O11: =IFERROR(N11/M11,0) -> 0.625 | P11: =_xlfn.XLOOKUP( L11, 'Candidate Data'!B:B, 'Candidate Data'!C:C, "Not Found" ) -> 47 | Q11: =_xlfn.XLOOKUP( L11, 'Candidate Data'!B:B, 'Candidate Data'!D:D, "Not Found" ) -> Commercial & Contract Law
A12: Recruiter3 | B12: 37 | C12: 26 | D12: =IFERROR(C12/B12,0) -> 0.7027027 | G12: Recruiter26 | H12: 38 | I12: 22 | J12: =IFERROR(I12/H12,0) -> 0.57894737 | L12: Recruiter26 | M12: 38 | N12: 22 | O12: =IFERROR(N12/M12,0) -> 0.57894737 | P12: =_xlfn.XLOOKUP( L12, 'Candidate Data'!B:B, 'Candidate Data'!C:C, "Not Found" ) -> 26 | Q12: =_xlfn.XLOOKUP( L12, 'Candidate Data'!B:B, 'Candidate Data'!D:D, "Not Found" ) -> Commercial & Contract Law
A13: Recruiter28 | B13: 26 | C13: 23 | D13: =IFERROR(C13/B13,0) -> 0.88461538 | G13: Recruiter28 | H13: 26 | I13: 23 | J13: =IFERROR(I13/H13,0) -> 0.88461538 | L13: Recruiter10 | M13: 111 | N13: 40 | O13: =IFERROR(N13/M13,0) -> 0.36036036 | P13: =_xlfn.XLOOKUP( L13, 'Candidate Data'!B:B, 'Candidate Data'!C:C, "Not Found" ) -> 39 | Q13: =_xlfn.XLOOKUP( L13, 'Candidate Data'!B:B, 'Candidate Data'!D:D, "Not Found" ) -> Corporate
A14: Recruiter26 | B14: 38 | C14: 22 | D14: =IFERROR(C14/B14,0) -> 0.57894737 | G14: Recruiter3 | H14: 37 | I14: 26 | J14: =IFERROR(I14/H14,0) -> 0.7027027 | L14: Recruiter5 | M14: 34 | N14: 12 | O14: =IFERROR(N14/M14,0) -> 0.35294118 | P14: =_xlfn.XLOOKUP( L14, 'Candidate Data'!B:B, 'Candidate Data'!C:C, "Not Found" ) -> 50 | Q14: =_xlfn.XLOOKUP( L14, 'Candidate Data'!B:B, 'Candidate Data'!D:D, "Not Found" ) -> Commercial & Contract Law
A15: Recruiter6 | B15: 63 | C15: 20 | D15: =IFERROR(C15/B15,0) -> 0.31746032 | G15: Recruiter4 | H15: 45 | I15: 12 | J15: =IFERROR(I15/H15,0) -> 0.26666667 | L15: Recruiter1 | M15: 133 | N15: 44 | O15: =IFERROR(N15/M15,0) -> 0.33082707 | P15: =_xlfn.XLOOKUP( L15, 'Candidate Data'!B:B, 'Candidate Data'!C:C, "Not Found" ) -> 35 | Q15: =_xlfn.XLOOKUP( L15, 'Candidate Data'!B:B, 'Candidate Data'!D:D, "Not Found" ) -> Litigation, Investigations & Dispute Resolution
A16: Recruiter15 | B16: 57 | C16: 15 | D16: =IFERROR(C16/B16,0) -> 0.26315789 | G16: Recruiter5 | H16: 34 | I16: 12 | J16: =IFERROR(I16/H16,0) -> 0.35294118 | L16: Recruiter6 | M16: 63 | N16: 20 | O16: =IFERROR(N16/M16,0) -> 0.31746032 | P16: =_xlfn.XLOOKUP( L16, 'Candidate Data'!B:B, 'Candidate Data'!C:C, "Not Found" ) -> 8 | Q16: =_xlfn.XLOOKUP( L16, 'Candidate Data'!B:B, 'Candidate Data'!D:D, "Not Found" ) -> Bankruptcy & Reorganization
A17: Recruiter8 | B17: 20 | C17: 13 | D17: =IFERROR(C17/B17,0) -> 0.65 | G17: Recruiter6 | H17: 63 | I17: 20 | J17: =IFERROR(I17/H17,0) -> 0.31746032 | L17: Recruiter2 | M17: 132 | N17: 41 | O17: =IFERROR(N17/M17,0) -> 0.31060606 | P17: =_xlfn.XLOOKUP( L17, 'Candidate Data'!B:B, 'Candidate Data'!C:C, "Not Found" ) -> 18 | Q17: =_xlfn.XLOOKUP( L17, 'Candidate Data'!B:B, 'Candidate Data'!D:D, "Not Found" ) -> Intellectual Property
... A20: Recruiter16 | B20: 19 | C20: 5 | D20: =IFERROR(C20/B20,0) -> 0.26315789 | G20: Recruiter9 | H20: 33 | I20: 34 | J20: =IFERROR(I20/H20,0) -> 1.030303 | L20: Recruiter11 | M20: 121 | N20: 27 | O20: =IFERROR(N20/M20,0) -> 0.2231405 | P20: =_xlfn.XLOOKUP( L20, 'Candidate Data'!B:B, 'Candidate Data'!C:C, "Not Found" ) -> 4 | Q20: =_xlfn.XLOOKUP( L20, 'Candidate Data'!B:B, 'Candidate Data'!D:D, "Not Found" ) -> Commercial & Contract Law
A21: Recruiter27 | B21: 7 | C21: 4 | D21: =IFERROR(C21/B21,0) -> 0.57142857
A22: Recruiter14 | B22: 3 | C22: 3 | D22: =IFERROR(C22/B22,0) -> 1
A23: Recruiter38 | B23: 3 | C23: 3 | D23: =IFERROR(C23/B23,0) -> 1
A24: Recruiter55 | B24: 4 | C24: 3 | D24: =IFERROR(C24/B24,0) -> 0.75
A25: Recruiter39 | B25: 2 | C25: 3 | D25: =IFERROR(C25/B25,0) -> 1.5
A26: Recruiter45 | B26: 3 | C26: 2 | D26: =IFERROR(C26/B26,0) -> 0.66666667
A27: Recruiter54 | B27: 1 | C27: 2 | D27: =IFERROR(C27/B27,0) -> 2
A28: Recruiter29 | B28: 5 | C28: 2 | D28: =IFERROR(C28/B28,0) -> 0.4
A29: Recruiter25 | B29: 4 | C29: 2 | D29: =IFERROR(C29/B29,0) -> 0.5
A30: Recruiter23 | C30: 2 | D30: =IFERROR(C30/B30,0) -> 0
A31: Recruiter42 | B31: 4 | C31: 2 | D31: =IFERROR(C31/B31,0) -> 0.5
A32: Recruiter12 | B32: 25 | C32: 2 | D32: =IFERROR(C32/B32,0) -> 0.08
A33: Recruiter18 | B33: 9 | C33: 2 | D33: =IFERROR(C33/B33,0) -> 0.22222222
A34: Recruiter34 | B34: 2 | C34: 2 | D34: =IFERROR(C34/B34,0) -> 1
A35: Recruiter32 | B35: 6 | C35: 2 | D35: =IFERROR(C35/B35,0) -> 0.33333333
A36: Recruiter43 | B36: 6 | C36: 1 | D36: =IFERROR(C36/B36,0) -> 0.16666667
A37: Recruiter40 | B37: 3 | C37: 1 | D37: =IFERROR(C37/B37,0) -> 0.33333333
A38: Recruiter47 | B38: 1 | C38: 1 | D38: =IFERROR(C38/B38,0) -> 1
A39: Recruiter48 | C39: 1 | D39: =IFERROR(C39/B39,0) -> 0
A40: Recruiter36 | B40: 4 | C40: 1 | D40: =IFERROR(C40/B40,0) -> 0.25
A41: Recruiter20 | B41: 6 | C41: 1 | D41: =IFERROR(C41/B41,0) -> 0.16666667
A42: Recruiter30 | B42: 8 | C42: 1 | D42: =IFERROR(C42/B42,0) -> 0.125
A43: Recruiter51 | B43: 11 | C43: 1 | D43: =IFERROR(C43/B43,0) -> 0.090909091
A44: Recruiter35 | B44: 2 | C44: 1 | D44: =IFERROR(C44/B44,0) -> 0.5
...

Sheet DashBoard
J18: Recruiters | K18: Phone Screen | L18: Waitlist | M18: Conversion Rate | N18: PQE | O18: Practice Areas
J19: Recruiter9 | K19: 33 | L19: 34 | M19: =IFERROR(L19/K19,0) -> 1.030303 | N19: =_xlfn.XLOOKUP( J19, 'Candidate Data'!B:B, 'Candidate Data'!C:C, "Not Found" ) -> 2 | O19: =_xlfn.XLOOKUP( J19, 'Candidate Data'!B:B, 'Candidate Data'!D:D, "Not Found" ) -> Data Privacy & Cybersecurity
J20: Recruiter28 | K20: 26 | L20: 23 | M20: =IFERROR(L20/K20,0) -> 0.88461538 | N20: =_xlfn.XLOOKUP( J20, 'Candidate Data'!B:B, 'Candidate Data'!C:C, "Not Found" ) -> 34 | O20: =_xlfn.XLOOKUP( J20, 'Candidate Data'!B:B, 'Candidate Data'!D:D, "Not Found" ) -> Commercial & Contract Law
J21: Recruiter21 | K21: 44 | L21: 38 | M21: =IFERROR(L21/K21,0) -> 0.86363636 | N21: =_xlfn.XLOOKUP( J21, 'Candidate Data'!B:B, 'Candidate Data'!C:C, "Not Found" ) -> 4 | O21: =_xlfn.XLOOKUP( J21, 'Candidate Data'!B:B, 'Candidate Data'!D:D, "Not Found" ) -> Commercial & Contract Law
J22: Recruiter3 | K22: 37 | L22: 26 | M22: =IFERROR(L22/K22,0) -> 0.7027027 | N22: =_xlfn.XLOOKUP( J22, 'Candidate Data'!B:B, 'Candidate Data'!C:C, "Not Found" ) -> 1 | O22: =_xlfn.XLOOKUP( J22, 'Candidate Data'!B:B, 'Candidate Data'!D:D, "Not Found" ) -> Regulatory & Compliance
J23: Recruiter8 | K23: 20 | L23: 13 | M23: =IFERROR(L23/K23,0) -> 0.65 | N23: =_xlfn.XLOOKUP( J23, 'Candidate Data'!B:B, 'Candidate Data'!C:C, "Not Found" ) -> 47 | O23: =_xlfn.XLOOKUP( J23, 'Candidate Data'!B:B, 'Candidate Data'!D:D, "Not Found" ) -> Finance
J24: Recruiter7 | K24: 48 | L24: 30 | M24: =IFERROR(L24/K24,0) -> 0.625 | N24: =_xlfn.XLOOKUP( J24, 'Candidate Data'!B:B, 'Candidate Data'!C:C, "Not Found" ) -> 47 | O24: =_xlfn.XLOOKUP( J24, 'Candidate Data'!B:B, 'Candidate Data'!D:D, "Not Found" ) -> Commercial & Contract Law
J25: Recruiter26 | K25: 38 | L25: 22 | M25: =IFERROR(L25/K25,0) -> 0.57894737 | N25: =_xlfn.XLOOKUP( J25, 'Candidate Data'!B:B, 'Candidate Data'!C:C, "Not Found" ) -> 26 | O25: =_xlfn.XLOOKUP( J25, 'Candidate Data'!B:B, 'Candidate Data'!D:D, "Not Found" ) -> Commercial & Contract Law
J26: Recruiter10 | K26: 111 | L26: 40 | M26: =IFERROR(L26/K26,0) -> 0.36036036 | N26: =_xlfn.XLOOKUP( J26, 'Candidate Data'!B:B, 'Candidate Data'!C:C, "Not Found" ) -> 39 | O26: =_xlfn.XLOOKUP( J26, 'Candidate Data'!B:B, 'Candidate Data'!D:D, "Not Found" ) -> Corporate
J27: Recruiter5 | K27: 34 | L27: 12 | M27: =IFERROR(L27/K27,0) -> 0.35294118 | N27: =_xlfn.XLOOKUP( J27, 'Candidate Data'!B:B, 'Candidate Data'!C:C, "Not Found" ) -> 50 | O27: =_xlfn.XLOOKUP( J27, 'Candidate Data'!B:B, 'Candidate Data'!D:D, "Not Found" ) -> Commercial & Contract Law
J28: Recruiter1 | K28: 133 | L28: 44 | M28: =IFERROR(L28/K28,0) -> 0.33082707 | N28: =_xlfn.XLOOKUP( J28, 'Candidate Data'!B:B, 'Candidate Data'!C:C, "Not Found" ) -> 35 | O28: =_xlfn.XLOOKUP( J28, 'Candidate Data'!B:B, 'Candidate Data'!D:D, "Not Found" ) -> Litigation, Investigations & Dispute Resolution
J29: Recruiter6 | K29: 63 | L29: 20 | M29: =IFERROR(L29/K29,0) -> 0.31746032 | N29: =_xlfn.XLOOKUP( J29, 'Candidate Data'!B:B, 'Candidate Data'!C:C, "Not Found" ) -> 8 | O29: =_xlfn.XLOOKUP( J29, 'Candidate Data'!B:B, 'Candidate Data'!D:D, "Not Found" ) -> Bankruptcy & Reorganization
J30: Recruiter2 | K30: 132 | L30: 41 | M30: =IFERROR(L30/K30,0) -> 0.31060606 | N30: =_xlfn.XLOOKUP( J30, 'Candidate Data'!B:B, 'Candidate Data'!C:C, "Not Found" ) -> 18 | O30: =_xlfn.XLOOKUP( J30, 'Candidate Data'!B:B, 'Candidate Data'!D:D, "Not Found" ) -> Intellectual Property
... J33: Recruiter11 | K33: 121 | L33: 27 | M33: =IFERROR(L33/K33,0) -> 0.2231405 | N33: =_xlfn.XLOOKUP( J33, 'Candidate Data'!B:B, 'Candidate Data'!C:C, "Not Found" ) -> 4 | O33: =_xlfn.XLOOKUP( J33, 'Candidate Data'!B:B, 'Candidate Data'!D:D, "Not Found" ) -> Commercial & Contract Law
